Workbook

Sheet ÇEKİ LİSTESİ (1)
A1: Tarih : Date Sayfa Nr : Page Nr : | C1: ='ÇALIŞMA SAYFASI'!C2 -> 46049 | D1: ÇEKİ LİSTESİ /PACKING LIST
C2: 1 / 1
B3: Fb.Nr./ Serial Nr | D3: : | E3: ='ÇALIŞMA SAYFASI'!E2 -> PA600-44&53 | H3: Müşteri / Client : | J3: ='ÇALIŞMA SAYFASI'!G2 -> SONELGAZ
B4: Güç / Rated Power (MVA) | D4: : | E4: ='ÇALIŞMA SAYFASI'!E4 -> 120 | H4: Adres / Location : | J4: ='ÇALIŞMA SAYFASI'!G4 -> ALGERIA
B5: Gerilim / Rated Voltage (kV) | D5: : | E5: ='ÇALIŞMA SAYFASI'!E6 -> 220 | M5: 44665
B6: Ölçü Resmi Nr. / Dimensional Drw.Nr. | F6: : | G6: ='ÇALIŞMA SAYFASI'!M4 -> T01128371 | M6: TOPLAM YAG : | N6: 52000
B7: Nakil Ölçü Resmi Nr./Transport Dimensional Drw.Nr. | F7: : | G7: ='ÇALIŞMA SAYFASI'!M3 -> T01128380 | M7: YAG CİNSİ : | N7: NYNAS NYTRO LYRA X
B8: Son Montaj Resmi Nr./Final Assembly Drw.Nr. | F8: : | G8: ='ÇALIŞMA SAYFASI'!M2 -> T01140490
B9: Project Manager | F9: : | G9: ACHAFI MAHAMAT
M10: EMİLEN YAG MİKTARI | P10: DİPTE KALAN YAG HESABI
C11: Transformatör yağlı, kapak altından …………. mm indirilmiş | P11: UZUNLUK | Q11: GENİŞLİK
C12: Transformer Partly Filled With Oil Up to ………….mm Below Tank Cover | R12: =P12*Q12*0.03*0.7*0.85/1000 -> 0 | S12: =M11+R12 -> 0
C13: Transformatör yağsız / Transformer Without Oil | J13: ÖLÇÜLER DEGİŞTİ
C14: Kuru Hava Basıldı / Dry Air Filled | J14: ÖLÇÜLER DEGİŞEBİLİR | O14: TOPLAM SEVK OLACAK YAG MİKTARI | S14: =N6-S12 -> 52000
C15: Gaz basıncı …220... mbar / Dry Air Pressure ...220.. mbar | J15: İLAVE SANDIK
C16: Kuru Hava Tüpü Montajı Var / Dry Air Tube Assembled | J16: YEDEK MALZEME VAR
C17: Darbe kaydedici / Shock Recorder | F17: Type: | G17: Electronic | H17: Pcs: | I17: 2
C18: Hazır Olan Malzemeler
B20: Trafo Sevk Tarihi : | G20: Aksesuar Sevk Tarihi
B21: Transformer Delivery Date | G21: Accessories Delivery Date | M21: =M53=' PACKING LIST'!D59 -> FALSE | N21: =N53=' PACKING LIST'!E59 -> FALSE | O21: =O53=' PACKING LIST'!I59 -> FALSE
A23: KOLİ PACKAGE | D23: AĞIRLIK WEIGHT | F23: ÖLÇÜLER DIMENSIONS | I23: MALZEME MATERIAL | M23: NET | N23: BRUT | O23: M3
A24: Koli Case Nr: | B24: Adet Quantity | C24: Ambalaj Cinsi Package Type | D24: Net Net (kg) | E24: Brüt Gross (kg) | F24: Uzunluk Length (mm) | G24: Genişlik Width (mm) | H24: Yükseklik Height (mm) | I24: Adet Quantity | J24: Cinsi Description
A25: 1 | B25: 1 | C25: Kısmı Ambalaj | D25: 173000 | E25: 173000 | F25: 9300 | G25: 3200 | H25: 4600 | I25: 1 | J25: Transformatör | M25: =B25*D25 -> 173000 | N25: =B25*E25 -> 173000 | O25: =B25*F25*G25*H25/1000000000 -> 136.896
M26: =B26*D26 -> 0 | N26: =B26*E26 -> 0 | O26: =B26*F26*G26*H26/1000000000 -> 0
A27: 2 | B27: 1 | C27: Kapalı Sandık | D27: 1450 | E27: 1600 | F27: 2100 | G27: 1000 | H27: 850 | I27: 4 | J27: Tekerlek ve Aksamları | M27: =B27*D27 -> 1450 | N27: =B27*E27 -> 1600 | O27: =B27*F27*G27*H27/1000000000 -> 1.785
A28: 3 | B28: 1 | C28: Kapalı Sandık | D28: 1200 | E28: 1500 | F28: 3050 | G28: 900 | H28: 800 | I28: 2 | J28: Travers Konsolları Yan | M28: =B28*D28 -> 1200 | N28: =B28*E28 -> 1500 | O28: =B28*F28*G28*H28/1000000000 -> 2.196
A29: 4 | B29: 1 | C29: Kapalı Sandık | D29: 1400 | E29: 1700 | F29: 3050 | G29: 1000 | H29: 800 | I29: 1 | J29: Travers Konsolları Orta | M29: =B29*D29 -> 1400 | N29: =B29*E29 -> 1700 | O29: =B29*F29*G29*H29/1000000000 -> 2.44
A30: 5 | B30: 1 | C30: Kapalı Sandık | D30: 2200 | E30: 2700 | F30: 4600 | G30: 1850 | H30: 2600 | I30: 1 | J30: Genleşme Kabı ve Nem Alıcılar | M30: =B30*D30 -> 2200 | N30: =B30*E30 -> 2700 | O30: =B30*F30*G30*H30/1000000000 -> 22.126
A31: 6-7 | B31: 2 | C31: Kapalı Sandık | D31: 1100 | E31: 1400 | F31: 2850 | G31: 1700 | H31: 1375 | I31: 2 | J31: Radyatör | M31: =B31*D31 -> 2200 | N31: =B31*E31 -> 2800 | O31: =B31*F31*G31*H31/1000000000 -> 13.32375
A32: 8-15 | B32: 8 | C32: Kapalı Sandık | D32: 1650 | E32: 2100 | F32: 2850 | G32: 1700 | H32: 1925 | I32: 3 | J32: Radyatör | M32: =B32*D32 -> 13200 | N32: =B32*E32 -> 16800 | O32: =B32*F32*G32*H32/1000000000 -> 74.613
A33: 16-17 | B33: 2 | C33: Kapalı Sandık | D33: 315 | E33: 700 | F33: 3650 | G33: 1350 | H33: 950 | I33: 3 | J33: Fan | M33: =B33*D33 -> 630 | N33: =B33*E33 -> 1400 | O33: =B33*F33*G33*H33/1000000000 -> 9.36225
A34: 18-19 | B34: 2 | C34: Kapalı Sandık | D34: 420 | E34: 950 | F34: 4800 | G34: 1350 | H34: 950 | I34: 4 | J34: Fan | M34: =B34*D34 -> 840 | N34: =B34*E34 -> 1900 | O34: =B34*F34*G34*H34/1000000000 -> 12.312
A35: 20 | B35: 1 | C35: Kapalı Sandık | D35: 700 | E35: 900 | F35: 2000 | G35: 1550 | H35: 2000 | I35: 2 | J35: YG DOM (1U-1W) | M35: =B35*D35 -> 700 | N35: =B35*E35 -> 900 | O35: =B35*F35*G35*H35/1000000000 -> 6.2
A36: 21 | B36: 1 | C36: Kapalı Sandık | D36: 350 | E36: 450 | F36: 1900 | G36: 1250 | H36: 1800 | I36: 2 | J36: YG DOM (1V-1N) | M36: =B36*D36 -> 350 | N36: =B36*E36 -> 450 | O36: =B36*F36*G36*H36/1000000000 -> 4.275
A37: 22 | B37: 1 | C37: Kapalı Sandık | D37: 1700 | E37: 2200 | F37: 5000 | G37: 1300 | H37: 1200 | I37: 40 | J37: Depo Konsolu ve Diğer Aksamlar | M37: =B37*D37 -> 1700 | N37: =B37*E37 -> 2200 | O37: =B37*F37*G37*H37/1000000000 -> 7.8
A38: 23 | B38: 1 | C38: Kapalı Sandık | D38: 800 | E38: 1300 | F38: 5100 | G38: 1300 | H38: 1300 | I38: 1+1Set | J38: Trafo Merdiveni + Boru Donanım | M38: =B38*D38 -> 800 | N38: =B38*E38 -> 1300 | O38: =B38*F38*G38*H38/1000000000 -> 8.619
A39: 24 | B39: 1 | C39: Kapalı Sandık | D39: 800 | E39: 1000 | F39: 3050 | G39: 1000 | H39: 900 | I39: 1 Set | J39: Aksesuar Malzemeleri + Trafo Montaj Ekipmanları | M39: =B39*D39 -> 800 | N39: =B39*E39 -> 1000 | O39: =B39*F39*G39*H39/1000000000 -> 2.745
A40: 25-27 | B40: 3 | C40: Kendi Sandıgı | D40: 315 | E40: 438 | F40: 4500 | G40: 600 | H40: 700 | I40: 1 | J40: YG Bushing | M40: =B40*D40 -> 945 | N40: =B40*E40 -> 1314 | O40: =B40*F40*G40*H40/1000000000 -> 5.67
A41: 28 | B41: 1 | C41: Kendi Sandıgı | D41: 295 | E41: 395 | F41: 3900 | G41: 600 | H41: 700 | I41: 1 | J41: YG N Bushing | M41: =B41*D41 -> 295 | N41: =B41*E41 -> 395 | O41: =B41*F41*G41*H41/1000000000 -> 1.638
A42: 29 | B42: 1 | C42: Kendi Sandıgı | D42: 180 | E42: 270 | F42: 2250 | G42: 1130 | H42: 600 | I42: 3 | J42: AG Bushing | M42: =B42*D42 -> 180 | N42: =B42*E42 -> 270 | O42: =B42*F42*G42*H42/1000000000 -> 1.5255
...

Sheet  PACKING LIST
H1: GRID SOLUTIONS ENERJI END. A.S BARIS MH. GUNEY YANYOL CD NO.320 41410, GEBZE KOCAELI- TURKEY TEL+902626483371 FAX+902626427040
B5: FB NR:
B6: PA600-44
L7: ='ÇALIŞMA SAYFASI'!C2 -> 46049
E9: PACKING LIST
D11: NET | E11: GROSS | F11: DIMENSIONS (CM) | J11: Transport CBM | K11: PIECES | L11: Content of The
B12: CASE NUMBER | C12: Packages | D12: WEIGHT (Kgs) | E12: WEIGHT(Kgs) | F12: L | G12: W | H12: H | I12: M3 | L12: Cases
B13: PA600-44-01 | C13: W.CRATE | D13: 173000 | E13: 173000 | F13: 930 | G13: 320 | H13: 460 | I13: =F13*G13*H13/1000000 -> 136.896 | J13: =I13 -> 136.896 | K13: 1 | L13: TRANSFORMER MAIN BODY
B14: PA600-44-02 | C14: W.CASE | D14: 1450 | E14: 1600 | F14: 210 | G14: 100 | H14: 85 | I14: =F14*G14*H14/1000000 -> 1.785 | J14: =E14*4.5/1000 -> 7.2 | K14: 4 | L14: WHEEL ASSEMBLY
B15: PA600-44-03 | C15: W.CASE | D15: 1200 | E15: 1500 | F15: 305 | G15: 90 | H15: 80 | I15: =F15*G15*H15/1000000 -> 2.196 | J15: =E15*4.5/1000 -> 6.75 | K15: 2 | L15: TRAVERSE CONSOLE
B16: PA600-44-04 | C16: W.CASE | D16: 1400 | E16: 1700 | F16: 305 | G16: 100 | H16: 80 | I16: =F16*G16*H16/1000000 -> 2.44 | J16: =E16*4.5/1000 -> 7.65 | K16: 1 | L16: TRAVERSE CONSOLE
B17: PA600-44-05 | C17: W.CASE | D17: 2200 | E17: 2700 | F17: 460 | G17: 185 | H17: 260 | I17: =F17*G17*H17/1000000 -> 22.126 | J17: =E17*4.5/1000 -> 12.15 | K17: 1 | L17: CONSERVATOR
B18: PA600-44-06 | C18: W.CASE | D18: 1100 | E18: 1400 | F18: 285 | G18: 170 | H18: 137.5 | I18: =F18*G18*H18/1000000 -> 6.661875 | J18: =E18*4.5/1000 -> 6.3 | K18: 2 | L18: RADIATOR
B19: PA600-44-07 | C19: W.CASE | D19: 1100 | E19: 1400 | F19: 285 | G19: 170 | H19: 137.5 | I19: =F19*G19*H19/1000000 -> 6.661875 | J19: =E19*4.5/1000 -> 6.3 | K19: 2 | L19: RADIATOR
B20: PA600-44-08 | C20: W.CASE | D20: 1650 | E20: 2100 | F20: 285 | G20: 170 | H20: 192.5 | I20: =F20*G20*H20/1000000 -> 9.326625 | J20: =E20*4.5/1000 -> 9.45 | K20: 3 | L20: RADIATOR
B21: PA600-44-09 | C21: W.CASE | D21: 1650 | E21: 2100 | F21: 285 | G21: 170 | H21: 192.5 | I21: =F21*G21*H21/1000000 -> 9.326625 | J21: =E21*4.5/1000 -> 9.45 | K21: 3 | L21: RADIATOR
B22: PA600-44-10 | C22: W.CASE | D22: 1650 | E22: 2100 | F22: 285 | G22: 170 | H22: 192.5 | I22: =F22*G22*H22/1000000 -> 9.326625 | J22: =E22*4.5/1000 -> 9.45 | K22: 3 | L22: RADIATOR
B23: PA600-44-11 | C23: W.CASE | D23: 1650 | E23: 2100 | F23: 285 | G23: 170 | H23: 192.5 | I23: =F23*G23*H23/1000000 -> 9.326625 | J23: =E23*4.5/1000 -> 9.45 | K23: 3 | L23: RADIATOR
B24: PA600-44-12 | C24: W.CASE | D24: 1650 | E24: 2100 | F24: 285 | G24: 170 | H24: 192.5 | I24: =F24*G24*H24/1000000 -> 9.326625 | J24: =E24*4.5/1000 -> 9.45 | K24: 3 | L24: RADIATOR
B25: PA600-44-13 | C25: W.CASE | D25: 1650 | E25: 2100 | F25: 285 | G25: 170 | H25: 192.5 | I25: =F25*G25*H25/1000000 -> 9.326625 | J25: =E25*4.5/1000 -> 9.45 | K25: 3 | L25: RADIATOR
... B34: PA600-44-22 | C34: W.CASE | D34: 1700 | E34: 2200 | F34: 500 | G34: 130 | H34: 120 | I34: =F34*G34*H34/1000000 -> 7.8 | J34: =E34*4.5/1000 -> 9.9 | K34: 40 | L34: CONSERVATOR SUPPORT
B35: PA600-44-23 | C35: W.CASE | D35: 800 | E35: 1300 | F35: 510 | G35: 130 | H35: 130 | I35: =F35*G35*H35/1000000 -> 8.619 | J35: =E35*4.5/1000 -> 5.85 | K35: 1 SET | L35: LADDER & PIPES
B36: PA600-44-24 | C36: W.CASE | D36: 800 | E36: 1000 | F36: 305 | G36: 100 | H36: 90 | I36: =F36*G36*H36/1000000 -> 2.745 | J36: =E36*4.5/1000 -> 4.5 | K36: 1 SET | L36: ACCESSORIES
B37: PA600-44-25 | C37: W.CASE | D37: 315 | E37: 438 | F37: 450 | G37: 60 | H37: 70 | I37: =F37*G37*H37/1000000 -> 1.89 | J37: =E37*4.5/1000 -> 1.971 | K37: 1 | L37: HV BUSHING
B38: PA600-44-26 | C38: W.CASE | D38: 315 | E38: 438 | F38: 450 | G38: 60 | H38: 70 | I38: =F38*G38*H38/1000000 -> 1.89 | J38: =E38*4.5/1000 -> 1.971 | K38: 1 | L38: HV BUSHING
B39: PA600-44-27 | C39: W.CASE | D39: 315 | E39: 438 | F39: 450 | G39: 60 | H39: 70 | I39: =F39*G39*H39/1000000 -> 1.89 | J39: =E39*4.5/1000 -> 1.971 | K39: 1 | L39: HV BUSHING
B40: PA600-44-28 | C40: W.CASE | D40: 295 | E40: 395 | F40: 390 | G40: 60 | H40: 70 | I40: =F40*G40*H40/1000000 -> 1.638 | J40: =E40*4.5/1000 -> 1.7775 | K40: 1 | L40: N BUSHING
B41: PA600-44-29 | C41: W.CASE | D41: 180 | E41: 270 | F41: 225 | G41: 113 | H41: 60 | I41: =F41*G41*H41/1000000 -> 1.5255 | J41: =E41*4.5/1000 -> 1.215 | K41: 3 | L41: LV BUSHING
B42: PA600-44-30 | C42: W.CASE | D42: 48 | E42: 91 | F42: 170 | G42: 38 | H42: 58 | I42: =F42*G42*H42/1000000 -> 0.37468 | J42: =E42*4.5/1000 -> 0.4095 | K42: 1 | L42: N BUSHING
B43: PA600-44-31 | C43: W.CASE | D43: 60 | E43: 102 | F43: 195 | G43: 45 | H43: 60 | I43: =F43*G43*H43/1000000 -> 0.5265 | J43: =E43*4.5/1000 -> 0.459 | K43: 1 | L43: TERTIARY BUSHING
B44: PA600-44-32 | C44: W.CASE | D44: 60 | E44: 102 | F44: 195 | G44: 45 | H44: 60 | I44: =F44*G44*H44/1000000 -> 0.5265 | J44: =E44*4.5/1000 -> 0.459 | K44: 1 | L44: TERTIARY BUSHING
B45: PA600-44-33 | C45: W.CASE | D45: 60 | E45: 102 | F45: 195 | G45: 45 | H45: 60 | I45: =F45*G45*H45/1000000 -> 0.5265 | J45: =E45*4.5/1000 -> 0.459 | K45: 1 | L45: TERTIARY BUSHING
B46: PA600-44-34 | C46: W.CASE | D46: 60 | E46: 102 | F46: 195 | G46: 45 | H46: 60 | I46: =F46*G46*H46/1000000 -> 0.5265 | J46: =E46*4.5/1000 -> 0.459 | K46: 1 | L46: TERTIARY BUSHING
B47: PA600-44-35 | C47: W. PALLET | D47: 728 | E47: 828 | F47: 120 | G47: 120 | H47: 110 | I47: =F47*G47*H47/1000000 -> 1.584 | J47: =E47*4.5/1000 -> 3.726 | K47: 4 | L47: TRANSFORMER OIL
B48: PA600-44-36 | C48: W. PALLET | D48: 728 | E48: 828 | F48: 120 | G48: 120 | H48: 110 | I48: =F48*G48*H48/1000000 -> 1.584 | J48: =E48*4.5/1000 -> 3.726 | K48: 4 | L48: TRANSFORMER OIL
... B58: PA600-44-46 | C58: W.CASE | D58: 600 | E58: 900 | F58: 280 | G58: 100 | H58: 100 | I58: =F58*G58*H58/1000000 -> 2.8 | J58: =E58*4.5/1000 -> 4.05 | K58: 1 | L58: TURRET
A59: TOTAL | B59: 46 | D59: =SUM(D13:D56) -> 209458 | E59: =SUM(E13:E56) -> 220008 | I59: =SUM(I13:I56) -> 331.84718 | J59: =SUM(J13:J56) -> 348.432

Sheet ÇALIŞMA SAYFASI
C1: ÇIKTI ALMA! ÇALIŞMA SAYFASI (KOLİ LİSTESİ DETAYI) ÇIKTI ALMA! DO NOT PRINT! WORKING PAGE (PACKING LIST DETAILS) DO NOT PRINT!
B2: Tarih: Date: | C2: 46049 | D2: FB NO: SERİAL NO: | E2: PA600-44&53 | F2: Müşteri : Client: | G2: SONELGAZ | K2: Son Montaj resmi No: | M2: T01140490
K3: Nakil Ölçü Resmi No: | M3: T01128380
D4: Güç (MVA): Rated Power: | E4: 120 | G4: ALGERIA | K4: Ölçü Resmi No: Dimensional Drw. No: | M4: T01128371
D6: Gerilim (kV): Rated Voltage: | E6: 220 | K6: Tekerlek Düzeni Res. No : | O6: Tek. Kod. No:
K7: Wheel Assembly Drw. No: | O7: Tek. Tesp. No:
C8: ÖLÇÜ RESMİ POZ.NO DIMENSIONAL DRW. POS. NO | D8: BARKOD NO BARCODE NO | E8: TANIM DESCRIPTION | F8: KOLİ NO CASE NO | G8: MİKTAR QUANTITY | H8: BİRİM UNIT | I8: PAKETLEYEN PACKER | J8: KONTROL CHECK | K8: REFERANS REFERENCE | N8: AÇIKLAMA REMARKS
A9: No | K9: RESİM NO: DRW. NO: | L9: ALT RESİM NO: DRW. NO: | M9: POZ NO: POS. NO:
A10: 1 | B10: FALSE | D10: FCT01120660 | E10: Transformatör \Transformer Main Body | F10: 1 | G10: 1 | H10: ADET
A11: 3 | B11: FALSE | C11: BZ150 | D11: FCT00924920 | E11: Firma plakası \Name Plate | F11: 1 | G11: 1 | H11: ADET
A12: 8 | B12: FALSE | C12: AE001 | D12: FC3097144-01 | E12: Tekerlek Düzeni \Wheel Assembly | F12: 2 | G12: 4 | H12: ADET
A13: 9 | B13: FALSE | C13: AE001 | D13: FC3097824 | E13: İki Parçalı Flanş \Flange | F13: 2 | G13: 4 | H13: ADET | N13: MONTAJ KITI TEK.DUZ_70TON_FLNS2PARC_RAY_
A14: 10 | B14: FALSE | C14: AE001 | D14: FC3097771 | E14: Tekerlek Montajı FIBER GLAS PARCA FLANS,HGW ( 50TON TEK.) \Wheel Mounting | F14: 2 | G14: 4 | H14: ADET | N14: FIBER GLAS PARCA FLANS,HGW ( 50TON TEK.)
A15: 11 | B15: FALSE | C15: AE001 | D15: FC401212 | E15: Tekerlek Montajı IZOLASYON PARCASI BORU 27X5 X55=PA6 \Wheel Mounting | F15: 2 | G15: 32 | H15: ADET | N15: IZOLASYON PARCASI BORU 27X5 X55=PA6
A16: 12 | B16: FALSE | C16: AE001 | D16: FC401220 | E16: Tekerlek Montajı FIBER GLAS PARCA PUL,,HGW 28,0X40,0X 6,0 \Wheel Mounting | F16: 2 | G16: 32 | H16: ADET | N16: FIBER GLAS PARCA PUL,,HGW 28,0X40,0X 6,0
A17: 13 | B17: FALSE | C17: AE001 | D17: FC3095004-01 | E17: Tekerlek Montajı PUL 17,0X45,0X 5,0=CRNI \Wheel Mounting | F17: 2 | G17: 32 | H17: ADET | N17: PUL 17,0X45,0X 5,0=CRNI
A18: 14 | B18: FALSE | C18: AE001 | D18: FC402742 | E18: Tekerlek Montajı CIVATA 6 KS. BA. M16x80=A2-70 \Wheel Mounting | F18: 2 | G18: 32 | H18: ADET | N18: CIVATA 6 KS. BA. M16x80=A2-70
A19: 15 | B19: FALSE | C19: AE001 | D19: FC112044 | E19: Merkezleme Saplaması SAPLAMA OZEL \Centering Bolt | F19: 2 | G19: 4 | H19: ADET | N19: SAPLAMA OZEL
A20: 16 | B20: FALSE | C20: BZ115 | D20: FC571107 | E20: Tekerlek Freni \Wheel Blocking | F20: 2 | G20: 2 | H20: ADET | N20: ............ mm KOD: ............
A21: 257 | B21: TRUE | D21: SMC | E21: Traves Konsolu \Traves Console | F21: 3 | G21: 2 | H21: ADET
A22: 257 | B22: TRUE | D22: SMC | E22: Traves Konsolu \Traves Console | F22: 4 | G22: 1 | H22: ADET
A23: 17 | B23: FALSE | C23: BB085 | D23: SMC | E23: Genleşme Kabı \Conservator | F23: 5 | G23: 1 | H23: ADET
A24: 18 | B24: FALSE | D24: SMC | E24: Trafo Nem Alıcı Borusu \Trans. Dehydrating BreatherPipe | F24: 5 | G24: 1 | H24: ADET | K24: T10574774 | L24: PA600-43-53.21.00000 | M24: 2
A25: 19 | B25: FALSE | C25: AA345 | D25: FCT00787561 | E25: DN40 Vana \DN 40 Type Valve | F25: 5 | G25: 1 | H25: ADET
A26: 20 | B26: FALSE | C26: CL060 | D26: FCT01167974 | E26: Yağ Seviye Göstergesi \Oil Level Indicator | F26: 5 | G26: 1 | H26: ADET | N26: YAG SEVIYE GOSTERGESI MTO-STF160G/2CO/C5
A27: 20 | B27: FALSE | C27: CL064 | D27: FCT01167975 | E27: Yağ Seviye Göstergesi \Oil Level Indicator | F27: 5 | G27: 1 | H27: ADET | N27: YAG SEVIYE GOSTERGESI MTO-STF160G/2CO/C5
A28: 21 | B28: FALSE | C28: BZ150 | D28: FCT00924920 | E28: Firma plakası \Name Plate | F28: 5 | G28: 1 | H28: ADET
A29: 22 | B29: FALSE | C29: AT001 | D29: FC420793 | E29: Nem Alıcı \Dehydrating Breather | F29: 5 | G29: 1 | H29: ADET | N29: NEM ALICI DIN 42562-L5
A30: 22 | B30: FALSE | C30: AT005 | D30: FC401128 | E30: Nem Alıcı \Dehydrating Breather | F30: 5 | G30: 1 | H30: ADET | N30: NEM ALICI DIN 42562-L1
A31: 23 | B31: FALSE | C31: CF101 | D31: FCT00674569 | E31: Buchholz Rölesi \Buchholz Relay | F31: 5 | G31: 1 | H31: ADET | N31: Depo üstünde montajlı \Mounted on the conservator
A32: 24 | B32: FALSE | D32: FC4324045 | E32: Boya Son Kat RAL 9006_C5 \Touch up Paint | F32: 5 | G32: 3 | H32: ADET | N32: 6 Kg.
A33: 25 | B33: FALSE | D33: FC4324045-01 | E33: Sertleştirici \Paint Hardener | F33: 5 | G33: 3 | H33: ADET | N33: 0,7 Kg.
A34: 26 | B34: FALSE | D34: FC4324046 | E34: Kırmızı Astar Boya \Paint Red | F34: 5 | G34: 3 | H34: ADET | N34: EPOTAN HS MASTIC GRİ BA124G2305 \1.KAT ASTAR 3 KG
A35: 27 | B35: FALSE | D35: FC4324048 | E35: Gri Astar Boya \Paint Gray | F35: 5 | G35: 3 | H35: ADET | N35: YÜKSEK KATILI EPOKSİ ASTAR (RAL 7042) \ARAKAT ASTAR 3 KG
A36: 28 | B36: FALSE | D36: FC4324049 | E36: Beyaz Astar Boya \Paint White | F36: 5 | G36: 3 | H36: ADET | N36: ASTAR EPOXY SERT İLE (RAL 9010 ) \İç ASTAR 1 KG
A37: 33 | B37: FALSE | C37: AC600 | D37: FCT01140482 | E37: Radyatör \Radiator | F37: 6 | G37: 2 | H37: ADET
A38: 33 | B38: FALSE | C38: AC600 | D38: FCT01140482 | E38: Radyatör \Radiator | F38: 7 | G38: 2 | H38: ADET
A39: 33 | B39: FALSE | C39: AC600 | D39: FCT01140484 | E39: Radyatör \Radiator | F39: 8 | G39: 3 | H39: ADET
A40: 33 | B40: FALSE | C40: AC600 | D40: FCT01140484 | E40: Radyatör \Radiator | F40: 9 | G40: 1 | H40: ADET
A41: 33 | B41: FALSE | C41: AC600 | D41: FCT01140477 | E41: Radyatör \Radiator | F41: 9 | G41: 2 | H41: ADET
...

Sheet ÇIKTI SAYFASI
B1: KOLİ LİSTESİ DETAYI PACKING LIST DETAILS
A2: Tarih: Date: | B2: ='ÇALIŞMA SAYFASI'!C2 -> 46049 | C2: FB NO: SERİAL NO: | D2: ='ÇALIŞMA SAYFASI'!E2 -> PA600-44&53 | E2: Müşteri : Client: | F2: ='ÇALIŞMA SAYFASI'!G2 -> SONELGAZ | J2: Son Montaj Resmi No: | L2: ='ÇALIŞMA SAYFASI'!M2 -> T01140490
J3: Nakil Ölçü Resmi No: | L3: ='ÇALIŞMA SAYFASI'!M3 -> T01128380
A4: Sayfa No: Page No: | C4: Güç (MVA): Rated Power: | D4: ='ÇALIŞMA SAYFASI'!E4 -> 120 | E4: Adres: Location: | F4: ='ÇALIŞMA SAYFASI'!G4 -> ALGERIA | J4: Ölçü Resmi No: Dimensional Drw. No: | L4: ='ÇALIŞMA SAYFASI'!M4 -> T01128371
C6: Gerilim (kV): Rated Voltage: | D6: ='ÇALIŞMA SAYFASI'!E6 -> 220 | J6: Tekerlek Düzeni Res. No : | N6: Tek. Kod. No:
J7: Wheel Assembly Drw. No: | N7: Tek. Tesp. No:
A8: SIRA NO ITEM NO | B8: ÖLÇÜ RESMİ POZ. NO DIMENSIONAL DRW. POS. NO | C8: BARKOD NO BARCODE NO | D8: TANIM DESCRIPTION | E8: KOLİ NO CASE NO | F8: MİKTAR QUANTITY | G8: BİRİM UNIT | H8: PAKETLEYEN PACKER | I8: KONTROL CHECK | J8: REFERANS REFERENCE | M8: AÇIKLAMA REMARKS
J9: RESİM NO: DRW. NO: | K9: ALT RESİM NO: DRW. NO: | L9: POZ NO: POS. NO:
A10: 1 | C10: FCT01120660 | D10: Transformatör \Transformer Main Body | E10: 1 | F10: 1 | G10: ADET
A11: 2 | B11: BZ150 | C11: FCT00924920 | D11: Firma plakası \Name Plate | E11: 1 | F11: 1 | G11: ADET
A12: 3
A13: 4
A14: 5 | B14: AE001 | C14: FC3097144-01 | D14: Tekerlek Düzeni \Wheel Assembly | E14: 2 | F14: 4 | G14: ADET
A15: 6 | B15: AE001 | C15: FC3097824 | D15: İki Parçalı Flanş \Flange | E15: 2 | F15: 4 | G15: ADET | M15: MONTAJ KITI TEK.DUZ_70TON_FLNS2PARC_RAY_
A16: 7 | B16: AE001 | C16: FC3097771 | D16: Tekerlek Montajı FIBER GLAS PARCA FLANS,HGW ( 50TON TEK.) \Wheel Mounting | E16: 2 | F16: 4 | G16: ADET | M16: FIBER GLAS PARCA FLANS,HGW ( 50TON TEK.)
A17: 8 | B17: AE001 | C17: FC401212 | D17: Tekerlek Montajı IZOLASYON PARCASI BORU 27X5 X55=PA6 \Wheel Mounting | E17: 2 | F17: 32 | G17: ADET | M17: IZOLASYON PARCASI BORU 27X5 X55=PA6
A18: 9 | B18: AE001 | C18: FC401220 | D18: Tekerlek Montajı FIBER GLAS PARCA PUL,,HGW 28,0X40,0X 6,0 \Wheel Mounting | E18: 2 | F18: 32 | G18: ADET | M18: FIBER GLAS PARCA PUL,,HGW 28,0X40,0X 6,0
A19: 10 | B19: AE001 | C19: FC3095004-01 | D19: Tekerlek Montajı PUL 17,0X45,0X 5,0=CRNI \Wheel Mounting | E19: 2 | F19: 32 | G19: ADET | M19: PUL 17,0X45,0X 5,0=CRNI
A20: 11 | B20: AE001 | C20: FC402742 | D20: Tekerlek Montajı CIVATA 6 KS. BA. M16x80=A2-70 \Wheel Mounting | E20: 2 | F20: 32 | G20: ADET | M20: CIVATA 6 KS. BA. M16x80=A2-70
A21: 12 | B21: AE001 | C21: FC112044 | D21: Merkezleme Saplaması SAPLAMA OZEL \Centering Bolt | E21: 2 | F21: 4 | G21: ADET | M21: SAPLAMA OZEL
A22: 13 | B22: BZ115 | C22: FC571107 | D22: Tekerlek Freni \Wheel Blocking | E22: 2 | F22: 2 | G22: ADET | M22: ............ mm KOD: ............
A23: 14
A24: 15
A25: 16
A26: 17
A27: 18
A28: 19 | C28: SMC50100 | D28: Traves Konsolu \Traves Console | E28: 3 | F28: 2 | G28: ADET
A29: 20 | C29: SMC50101 | D29: Traves Konsolu \Traves Console | E29: 4 | F29: 1 | G29: ADET
A30: 21 | C30: FCT01140587 | D30: PLAKA IZOLASYON RESİM KODU Travers Konsol Montajı İçin | E30: 4 | F30: 1 | G30: SET | M30: PD
A31: 22 | C31: FCT01140587 | D31: PLAKA IZOLASYON 2730x250x12 MALZ:PA6 Travers Konsol Montajı İçin | E31: 4 | F31: 2 | G31: ADET | M31: PD
A32: 23 | C32: FCT01140587 | D32: PLAKA IZOLASYON 2730x800x12 MALZ:PA6 Travers Konsol Montajı İçin | E32: 4 | F32: 1 | G32: ADET | M32: PD
A33: 24 | C33: FC401212 | D33: IZOLASYON PARCASI BORU 27X5 X55=PA6 Travers Konsol Montajı İçin | E33: 4 | F33: 12 | G33: AD | M33: PD
A34: 25 | C34: FC401220 | D34: FIBER GLAS PARCA PUL,,HGW 28,0X40,0X 6,0 Travers Konsol Montajı İçin | E34: 4 | F34: 24 | G34: AD | M34: PD
A35: 26 | C35: FC3095004-01 | D35: PUL 17,0X45,0X 5,0=CRNI Travers Konsol Montajı İçin | E35: 4 | F35: 24 | G35: AD | M35: ND
A36: 27 | C36: FC402742 | D36: CIVATA 6 KS. BA. M16x80=A2-70 Travers Konsol Montajı İçin | E36: 4 | F36: 12 | G36: AD | M36: ND
A37: 28
A38: 29
A39: 30
A40: 31
A41: 32 | B41: BB085 | C41: SMC50102 | D41: Genleşme Kabı \Conservator | E41: 5 | F41: 1 | G41: ADET
...

Sheet İŞLETME CONTA TK.
B1: KOLİ LİSTESİ DETAYI PACKING LIST DETAILS
A2: Tarih: Date: | B2: ='ÇALIŞMA SAYFASI'!C2 -> 46049 | C2: FB NO: SERİAL NO: | D2: ='ÇALIŞMA SAYFASI'!E2 -> PA600-44&53 | E2: Müşteri : Client: | F2: ='ÇALIŞMA SAYFASI'!G2 -> SONELGAZ | J2: Son Montaj Resmi No: | L2: ='ÇALIŞMA SAYFASI'!M2 -> T01140490
J3: Nakil Ölçü Resmi No: | L3: ='ÇALIŞMA SAYFASI'!M3 -> T01128380
A4: Sayfa No: Page No: | C4: Güç (MVA): Rated Power: | D4: ='ÇALIŞMA SAYFASI'!E4 -> 120 | E4: Adres: Location: | F4: ='ÇALIŞMA SAYFASI'!G4 -> ALGERIA | J4: Ölçü Resmi No: Dimensional Drw. No: | L4: ='ÇALIŞMA SAYFASI'!M4 -> T01128371
C6: Gerilim (kV): Rated Voltage: | D6: ='ÇALIŞMA SAYFASI'!E6 -> 220 | J6: Tekerlek Düzeni Res. No : | N6: Tek. Kod. No:
J7: Wheel Assembly Drw. No: | N7: Tek. Tesp. No:
A8: SIRA NO ITEM NO | B8: ÖLÇÜ RESMİ POZ. NO DIMENSIONAL DRW. POS. NO | C8: BARKOD NO BARCODE NO | D8: TANIM DESCRIPTION | E8: KOLİ NO CASE NO | F8: MİKTAR QUANTITY | G8: BİRİM UNIT | H8: PAKETLEYEN PACKER | I8: KONTROL CHECK | J8: REFERANS REFERENCE | M8: AÇIKLAMA REMARKS
J9: RESİM NO: DRW. NO: | K9: ALT RESİM NO: DRW. NO: | L9: POZ NO: POS. NO:
A10: 1 | B10: 0001 | C10: FC3006240-20 | D10: CONTA O-RING RD10xD1= 335/L=1094 | E10: 24 | F10: 3 | G10: AD
A11: 2 | B11: 0002 | C11: FC3006240-20 | D11: CONTA O-RING RD10xD1= 335/L=1094 | E11: 24 | F11: 1 | G11: AD
A12: 3 | B12: 0003 | C12: FC3006240-03 | D12: CONTA O-RING RD10xD1= 150/L= 513 | E12: 24 | F12: 8 | G12: AD
A13: 4 | B13: 0004 | C13: FCT00769063 | D13: CONTA CONTA_NBR_700_0° | E13: 24 | F13: 1 | G13: AD
A14: 5 | B14: 0005 | C14: FCT00769372 | D14: CONTA CONTA_NBR_700_15° | E14: 24 | F14: 1 | G14: AD
A15: 6 | B15: 0006 | C15: FCT00769373 | D15: CONTA CONTA_NBR_700_20° | E15: 24 | F15: 2 | G15: AD
A16: 7 | B16: 0007 | C16: FCT01140547 | D16: CONTA VULKANIZE | E16: 24 | F16: 1 | G16: AD
A17: 8 | B17: 0008 | C17: FC17731 | D17: CONTA YUV. RD100X5,5 | E17: 24 | F17: 56 | G17: AD
A18: 9 | B18: 0009 | C18: FC403792 | D18: LASTIK YUV. A10-NB | E18: 24 | F18: 10 | G18: M
A19: 10 | B19: 0010 | C19: FCT00800458 | D19: CONTA O-RING DN80 NBR | E19: 24 | F19: 28 | G19: AD
A20: 11 | B20: 0011 | C20: FC402511 | D20: CONTA O-RİNG 45,0x5,5 A NBR70 DN 25 | E20: 24 | F20: 25 | G20: AD
A21: 12 | B21: 0012 | C21: FC402512 | D21: CONTA O-RİNG 65X6,0 A NBR70 DN 40 | E21: 24 | F21: 25 | G21: AD
... A25: 16 | B25: 0016 | C25: FCT00769061 | D25: CONTA CONTA_NBR_500_0° | E25: 24 | F25: 4 | G25: AD
A26: 17
A27: 18
A28: 19 | D28: Trafoların hepsi tam kurulmayacağı için imalatın kullanmayacağı contalar
A29: 20 | C29: FC12631 | D29: CONTA | E29: 24 | F29: 1 | G29: AD | M29: Contalar işletme ile plde verilen diğer contaları karşılaştır. İşletme contalarında yoksa eklet.
A30: 21 | C30: FC163505 | D30: CONTA DUZ 25- 68 | E30: 24 | F30: 1 | G30: AD
A31: 22 | C31: FCT00800458 | D31: CONTA O-RING DN80 NBR | E31: 24 | F31: 28 | G31: AD
A32: 23 | C32: FC402515 | D32: CONTA O-RİNG 100X8,0 A NBR70 DN 80 | E32: 24 | F32: 10 | G32: AD
A33: 24 | C33: FC402511 | D33: CONTA O-RİNG 45,0x5,5 A NBR70 DN 25 | E33: 24 | F33: 36 | G33: AD
A34: 25 | C34: FC402512 | D34: CONTA O-RİNG 65X6,0 A NBR70 DN 40 | E34: 24 | F34: 12 | G34: AD
A35: 26 | C35: FC402513 | D35: CONTA O-RİNG 78X6,0 A NBR70 DN 50 | E35: 24 | F35: 4 | G35: AD
A36: 27 | C36: FCT00733941 | D36: CONTA VITON CONTA, QUALITROL BGV | E36: 24 | F36: 2 | G36: AD
A37: 28 | C37: FCT00682818 | D37: CONTA VITON CONTA, TASMA BORUSU | E37: 24 | F37: 2 | G37: AD
A38: 29
A39: 30
A40: 31
A41: 32
A42: 33
A43: 34
A44: 35 | C44: FCT00803854 | D44: KONSOL FAN MONTAJI | E44: 24 | F44: 28 | G44: AD
...

Sheet TRAFO MONTAJ EKİPMANLARI 3K
B1: KOLİ LİSTESİ DETAYI PACKING LIST DETAILS
A2: Tarih: Date: | B2: ='ÇALIŞMA SAYFASI'!C2 -> 46049 | C2: FB NO: SERİAL NO: | D2: ='ÇALIŞMA SAYFASI'!E2 -> PA600-44&53 | E2: Müşteri : Client: | F2: ='ÇALIŞMA SAYFASI'!G2 -> SONELGAZ | J2: Son Montaj Resmi No: | L2: ='ÇALIŞMA SAYFASI'!M2 -> T01140490
J3: Nakil Ölçü Resmi No: | L3: ='ÇALIŞMA SAYFASI'!M3 -> T01128380
A4: Sayfa No: Page No: | C4: Güç (MVA): Rated Power: | D4: ='ÇALIŞMA SAYFASI'!E4 -> 120 | E4: Adres: Location: | F4: ='ÇALIŞMA SAYFASI'!G4 -> ALGERIA | J4: Ölçü Resmi No: Dimensional Drw. No: | L4: ='ÇALIŞMA SAYFASI'!M4 -> T01128371
C6: Gerilim (kV): Rated Voltage: | D6: ='ÇALIŞMA SAYFASI'!E6 -> 220 | J6: Tekerlek Düzeni Res. No : | N6: Tek. Kod. No:
J7: Wheel Assembly Drw. No: | N7: Tek. Tesp. No:
A8: SIRA NO ITEM NO | B8: ÖLÇÜ RESMİ POZ. NO DIMENSIONAL DRW. POS. NO | C8: BARKOD NO BARCODE NO | D8: TANIM DESCRIPTION | E8: KOLİ NO CASE NO | F8: MİKTAR QUANTITY | G8: BİRİM UNIT | H8: PAKETLEYEN PACKER | I8: KONTROL CHECK | J8: REFERANS REFERENCE | M8: AÇIKLAMA REMARKS
J9: RESİM NO: DRW. NO: | K9: ALT RESİM NO: DRW. NO: | L9: POZ NO: POS. NO:
A10: 1 | C10: FCT00098050 | D10: CIVATA 6 KS. BA. M 6X 10=A2-70 | E10: 24 | F10: 30 | G10: AD | M10: Kutuların / paketlerin üstünde keisnlikle kod olacak
A11: 2 | C11: FC400288 | D11: CIVATA 6 KS. BA. M 8X 35=A2-70 | E11: 24 | F11: 60 | G11: AD
A12: 3 | C12: FC400258 | D12: CIVATA 6 KS. BA. M10X 30=A2-70 | E12: 24 | F12: 120 | G12: AD
A13: 4 | C13: FCT00686323 | D13: CIVATA 6 KS. BA. M10x35=A4-70 | E13: 24 | F13: 40 | G13: AD
A14: 5 | C14: FC400292 | D14: CIVATA 6 KS. BA. M12X 30=A2-70 | E14: 24 | F14: 90 | G14: AD
A15: 6 | C15: FC400262 | D15: CIVATA 6 KS. BA. M12X 45=A2-70 | E15: 24 | F15: 130 | G15: AD
A16: 7 | C16: FC400363 | D16: CIVATA 6 KS. BA. M12X 50=A2-70 | E16: 24 | F16: 190 | G16: AD
A17: 8 | C17: FC400379 | D17: CIVATA 6 KS. BA. M16X 45=A2-70 | E17: 24 | F17: 20 | G17: AD
A18: 9 | C18: FC111 | D18: CIVATA 6 KS. BA. M16X 60=8.8=A4G | E18: 24 | F18: 120 | G18: AD
A19: 10 | C19: FC400375 | D19: CIVATA 6 KS. BA. M16X 60=A2-70 | E19: 24 | F19: 40 | G19: AD
A20: 11 | C20: FC400381 | D20: CIVATA 6 KS. BA. M16X 70=A2-70 | E20: 24 | F20: 120 | G20: AD
A21: 12 | C21: FCT00721333 | D21: CIVATA 6 KS. BA. M16X55=A2-70 | E21: 24 | F21: 30 | G21: AD
A22: 13 | C22: FC402742 | D22: CIVATA 6 KS. BA. M16x80=A2-70 | E22: 24 | F22: 30 | G22: AD
... A56: 47 | C56: FC400750 | D56: SOMUN 6 KS. BA. M20=A2-70..x | E56: 24 | F56: 80 | G56: AD

Sheet TRAFO MONTAJ EKİPMANLARI SO
B1: KOLİ LİSTESİ DETAYI PACKING LIST DETAILS
A2: Tarih: Date: | B2: ='ÇALIŞMA SAYFASI'!C2 -> 46049 | C2: FB NO: SERİAL NO: | D2: ='ÇALIŞMA SAYFASI'!E2 -> PA600-44&53 | E2: Müşteri : Client: | F2: ='ÇALIŞMA SAYFASI'!G2 -> SONELGAZ | J2: Son Montaj Resmi No: | L2: ='ÇALIŞMA SAYFASI'!M2 -> T01140490
J3: Nakil Ölçü Resmi No: | L3: ='ÇALIŞMA SAYFASI'!M3 -> T01128380
A4: Sayfa No: Page No: | C4: Güç (MVA): Rated Power: | D4: ='ÇALIŞMA SAYFASI'!E4 -> 120 | E4: Adres: Location: | F4: ='ÇALIŞMA SAYFASI'!G4 -> ALGERIA | J4: Ölçü Resmi No: Dimensional Drw. No: | L4: ='ÇALIŞMA SAYFASI'!M4 -> T01128371
C6: Gerilim (kV): Rated Voltage: | D6: ='ÇALIŞMA SAYFASI'!E6 -> 220 | J6: Tekerlek Düzeni Res. No : | N6: Tek. Kod. No:
J7: Wheel Assembly Drw. No: | N7: Tek. Tesp. No:
A8: SIRA NO ITEM NO | B8: ÖLÇÜ RESMİ POZ. NO DIMENSIONAL DRW. POS. NO | C8: BARKOD NO BARCODE NO | D8: TANIM DESCRIPTION | E8: KOLİ NO CASE NO | F8: MİKTAR QUANTITY | G8: BİRİM UNIT | H8: PAKETLEYEN PACKER | I8: KONTROL CHECK | J8: REFERANS REFERENCE | M8: AÇIKLAMA REMARKS
J9: RESİM NO: DRW. NO: | K9: ALT RESİM NO: DRW. NO: | L9: POZ NO: POS. NO:
A10: 1 | B10: 0008 | C10: FC3098029 | D10: MONTAJ B.G.V. STANDART | E10: 24 | F10: 1 | G10: AD | J10: T01120674 | M10: Tepe Kodu
A11: 2 | B11: 0001 | C11: FC400270 | D11: SOMUN 6 KS. BA. M12=A2-70 | E11: 24 | F11: 6 | G11: AD | J11: T01120674
A12: 3 | B12: 0002 | C12: FC425882 | D12: PUL GENIS DUZ 13,0=A4 | E12: 24 | F12: 6 | G12: AD | J12: T01120674
A13: 4 | B13: 0004 | C13: FC12631 | D13: CONTA | E13: 24 | F13: 1 | G13: AD | J13: T01120674
A14: 5 | B14: 0005 | C14: FC400365 | D14: SAPLAMA M12x35 | E14: 24 | F14: 6 | G14: AD | J14: T01120674
A15: 6 | B15: 0009 | C15: FCT00733939 | D15: MONTAJ BASINC GIDER.VENTIL MONT.-QU-VITO | E15: 24 | F15: 2 | G15: AD | J15: T01120674 | M15: Tepe Kodu
A16: 7 | B16: 0001 | C16: FC400270 | D16: SOMUN 6 KS. BA. M12=A2-70 | E16: 24 | F16: 12 | G16: AD | J16: T01120674
A17: 8 | B17: 0002 | C17: FC425882 | D17: PUL GENIS DUZ 13,0=A4 | E17: 24 | F17: 12 | G17: AD | J17: T01120674
A18: 9 | B18: 0004 | C18: FCT00733941 | D18: CONTA VITON CONTA, QUALITROL BGV | E18: 24 | F18: 2 | G18: AD | J18: T01120674
A19: 10 | B19: 0005 | C19: FC400365 | D19: SAPLAMA M12x35 | E19: 24 | F19: 12 | G19: AD | J19: T01120674
A20: 11 | B20: 0006 | C20: FC3006180 | D20: FLANS | E20: 24 | F20: 2 | G20: AD | J20: T01120674
A21: 12 | B21: 0010 | C21: FCT00682818 | D21: CONTA VITON CONTA, TASMA BORUSU | E21: 24 | F21: 2 | G21: AD | J21: T01120674
A22: 13 | B22: 0029 | C22: FC3095251-01 | D22: MONTAJ TOPRAKLAMA MONT. M6x16-200 | E22: 24 | F22: 12 | G22: AD | J22: T01120674 | M22: Tepe Kodu
A23: 14 | B23: 0001 | C23: FC421956 | D23: KABLO TOPRAKLAMA ORG.M6x16-200 | E23: 24 | F23: 12 | G23: AD | J23: T01120674
A24: 15 | B24: 0002 | C24: FC3095330-02 | D24: MONTAJ KITI TOPRAKLAMA ( M 6 ) | E24: 24 | F24: 24 | G24: AD | J24: T01120674
A25: 16 | B25: 0004 | C25: FCT00098050 | D25: CIVATA 6 KS. BA. M 6X 10=A2-70 | E25: 24 | F25: 24 | G25: AD | J25: T01120674
A26: 17 | B26: 0006 | C26: FC400298 | D26: PUL A 6,4=NRST | E26: 24 | F26: 24 | G26: AD | J26: T01120674
A27: 18 | B27: 0033 | C27: FC3095251-06 | D27: MONTAJ TOPRAKLAMA MONT. M12x200-200 | E27: 24 | F27: 40 | G27: AD | J27: T01120674 | M27: Tepe Kodu
A28: 19 | B28: 0001 | C28: FCT00679060 | D28: KABLO TOPRAKLAMA ORG.M12x200-200 | E28: 24 | F28: 40 | G28: AD | J28: T01120674
A29: 20 | B29: 0002 | C29: FC400292 | D29: CIVATA 6 KS. BA. M12X 30=A2-70 | E29: 24 | F29: 80 | G29: AD | J29: T01120674
A30: 21 | B30: 0004 | C30: FC400273 | D30: PUL A13,0=NRST | E30: 24 | F30: 80 | G30: AD | J30: T01120674
A31: 22 | B31: 0300 | C31: FC3007302-04 | D31: MONTAJ KITI CIV.BAGLANTI DN25-A2-70 | E31: 24 | F31: 23 | G31: AD | J31: T01132063 | M31: Tepe Kodu
A32: 23 | B32: 0001 | C32: FC402511 | D32: CONTA O-RİNG 45,0x5,5 A NBR70 DN 25 | E32: 24 | F32: 23 | G32: AD | J32: T01132063
A33: 24 | B33: 0002 | C33: FC400363 | D33: CIVATA 6 KS. BA. M12X 50=A2-70 | E33: 24 | F33: 92 | G33: AD | J33: T01132063
A34: 25 | B34: 0003 | C34: FC400270 | D34: SOMUN 6 KS. BA. M12=A2-70 | E34: 24 | F34: 92 | G34: AD | J34: T01132063
A35: 26 | B35: 0004 | C35: FC400273 | D35: PUL A13,0=NRST | E35: 24 | F35: 184 | G35: AD | J35: T01132063
A36: 27 | B36: 0301 | C36: FC400263 | D36: CIVATA,6KŞ.BA. M12X 60=A2-70 | E36: 24 | F36: 23 | G36: AD | J36: T01132063
A37: 28 | B37: 0302 | C37: FC400381 | D37: CIVATA 6 KS. BA. M16X 70=A2-70 | E37: 24 | F37: 5 | G37: AD | J37: T01132063
A38: 29 | B38: 0303 | C38: FC3007302-06 | D38: MONTAJ KITI CIV.BAGLANTI DN40-A2-70 | E38: 24 | F38: 5 | G38: AD | J38: T01132063 | M38: Tepe Kodu
A39: 30 | B39: 0001 | C39: FC402512 | D39: CONTA O-RİNG 65X6,0 A NBR70 DN 40 | E39: 24 | F39: 5 | G39: AD | J39: T01132063
A40: 31 | B40: 0002 | C40: FC400375 | D40: CIVATA 6 KS. BA. M16X 60=A2-70 | E40: 24 | F40: 20 | G40: AD | J40: T01132063
A41: 32 | B41: 0003 | C41: FC400380 | D41: SOMUN 6 KS. BA. M16=A2-70 | E41: 24 | F41: 20 | G41: AD | J41: T01132063
...

Sheet ÇALIŞMA SAYFASI YDK
C1: ÇIKTI ALMA! ÇALIŞMA SAYFASI (KOLİ LİSTESİ DETAYI) ÇIKTI ALMA! DO NOT PRINT! WORKING PAGE (PACKING LIST DETAILS) DO NOT PRINT!
B2: Tarih: Date: | C2: =TODAY() -> 46128 | D2: FB NO: SERİAL NO: | E2: PA600-43&53 | F2: Müşteri : Client: | G2: SONELGAZ | K2: Son Montaj resmi No: | M2: T01140490
K3: Nakil Ölçü Resmi No: | M3: T01128380
D4: Güç (MVA): Rated Power: | E4: 120 | K4: Ölçü Resmi No: Dimensional Drw. No: | M4: T01128371
D6: Gerilim (kV): Rated Voltage: | E6: 220 | K6: Tekerlek Düzeni Res. No : | O6: Tek. Kod. No:
K7: Wheel Assembly Drw. No: | O7: Tek. Tesp. No:
C8: ÖLÇÜ RESMİ POZ.NO DIMENSIONAL DRW. POS. NO | D8: BARKOD NO BARCODE NO | E8: TANIM DESCRIPTION | F8: KOLİ NO CASE NO | G8: MİKTAR QUANTITY | H8: BİRİM UNIT | I8: PAKETLEYEN PACKER | J8: KONTROL CHECK | K8: REFERANS REFERENCE | N8: AÇIKLAMA REMARKS
A9: No | K9: RESİM NO: DRW. NO: | L9: ALT RESİM NO: DRW. NO: | M9: POZ NO: POS. NO:
A10: 1 | B10: FALSE | D10: FCT01120660 | E10: Transformatör \Transformer Main Body | F10: 1 | G10: 1 | H10: ADET
A11: 2 | B11: FALSE | E11: Darbe Kayıt Cihazı \Shock Recorder | H11: ADET
A12: 3 | B12: FALSE | C12: BZ150 | D12: FCT00924920 | E12: Firma plakası \Name Plate | F12: 1 | G12: 1 | H12: ADET
A13: 4 | B13: FALSE | C13: BZ151 | D13: FCT00959727 | E13: İşaret Plakası \Rating Plate | G13: 1 | H13: ADET
A14: 5 | B14: FALSE | C14: BZ160 | D14: FCT00959729 | E14: Donanım Plakası \Piping Plate | G14: 1 | H14: ADET
A15: 6 | B15: FALSE | E15: Transport Konsolu \Transport Console | H15: ADET
A16: 7 | B16: FALSE | D16: FC3092407-03 | E16: Titreşim önleme takozu \Anti vibration pad | G16: 9 | H16: SET
A17: 8 | B17: FALSE | C17: AE001 | D17: FC3097144-01 | E17: Tekerlek Düzeni \Wheel Assembly | F17: 2 | G17: 4 | H17: ADET
A18: 9 | B18: FALSE | C18: AE001 | D18: FC3097824 | E18: İki Parçalı Flanş \Flange | F18: 2 | G18: 4 | H18: ADET | N18: MONTAJ KITI TEK.DUZ_70TON_FLNS2PARC_RAY_
A19: 10 | B19: FALSE | C19: AE001 | D19: FC3097771 | E19: Tekerlek Montajı FIBER GLAS PARCA FLANS,HGW ( 50TON TEK.) \Wheel Mounting | F19: 2 | G19: 4 | H19: ADET | N19: FIBER GLAS PARCA FLANS,HGW ( 50TON TEK.)
A20: 11 | B20: FALSE | C20: AE001 | D20: FC401212 | E20: Tekerlek Montajı IZOLASYON PARCASI BORU 27X5 X55=PA6 \Wheel Mounting | F20: 2 | G20: 32 | H20: ADET | N20: IZOLASYON PARCASI BORU 27X5 X55=PA6
A21: 12 | B21: FALSE | C21: AE001 | D21: FC401220 | E21: Tekerlek Montajı FIBER GLAS PARCA PUL,,HGW 28,0X40,0X 6,0 \Wheel Mounting | F21: 2 | G21: 32 | H21: ADET | N21: FIBER GLAS PARCA PUL,,HGW 28,0X40,0X 6,0
A22: 13 | B22: FALSE | C22: AE001 | D22: FC3095004-01 | E22: Tekerlek Montajı PUL 17,0X45,0X 5,0=CRNI \Wheel Mounting | F22: 2 | G22: 32 | H22: ADET | N22: PUL 17,0X45,0X 5,0=CRNI
A23: 14 | B23: FALSE | C23: AE001 | D23: FC402742 | E23: Tekerlek Montajı CIVATA 6 KS. BA. M16x80=A2-70 \Wheel Mounting | F23: 2 | G23: 32 | H23: ADET | N23: CIVATA 6 KS. BA. M16x80=A2-70
A24: 15 | B24: FALSE | C24: AE001 | D24: FC112044 | E24: Merkezleme Saplaması SAPLAMA OZEL \Centering Bolt | F24: 2 | G24: 4 | H24: ADET | N24: SAPLAMA OZEL
A25: 16 | B25: FALSE | C25: BZ115 | D25: FC571107 | E25: Tekerlek Freni \Wheel Blocking | F25: 2 | G25: 2 | H25: ADET | N25: ............ mm KOD: ............
A26: 17 | B26: FALSE | C26: BB085 | D26: SMC | E26: Genleşme Kabı \Conservator | F26: 5 | G26: 1 | H26: ADET
A27: 18 | B27: FALSE | D27: SMC | E27: Trafo Nem Alıcı Borusu \Trans. Dehydrating BreatherPipe | F27: 5 | G27: 1 | H27: ADET | K27: T10574774 | L27: PA600-43-53.21.00000 | M27: 2
A28: 19 | B28: FALSE | C28: AA345 | D28: FCT00787561 | E28: DN40 Vana \DN 40 Type Valve | F28: 5 | G28: 1 | H28: ADET
A29: 20 | B29: FALSE | C29: CL060 | D29: FCT01167974 | E29: Yağ Seviye Göstergesi \Oil Level Indicator | F29: 5 | G29: 1 | H29: ADET | N29: YAG SEVIYE GOSTERGESI MTO-STF160G/2CO/C5
A30: 20 | B30: FALSE | C30: CL064 | D30: FCT01167975 | E30: Yağ Seviye Göstergesi \Oil Level Indicator | F30: 5 | G30: 1 | H30: ADET | N30: YAG SEVIYE GOSTERGESI MTO-STF160G/2CO/C5
A31: 21 | B31: FALSE | C31: BZ150 | D31: FCT00924920 | E31: Firma plakası \Name Plate | F31: 5 | G31: 1 | H31: ADET
A32: 22 | B32: FALSE | C32: AT001 | D32: FC420793 | E32: Nem Alıcı \Dehydrating Breather | F32: 5 | G32: 1 | H32: ADET | N32: NEM ALICI DIN 42562-L5
A33: 22 | B33: FALSE | C33: AT005 | D33: FC401128 | E33: Nem Alıcı \Dehydrating Breather | F33: 5 | G33: 1 | H33: ADET | N33: NEM ALICI DIN 42562-L1
A34: 23 | B34: FALSE | C34: CF101 | D34: FCT00674569 | E34: Buchholz Rölesi \Buchholz Relay | F34: 5 | G34: 1 | H34: ADET | N34: Depo üstünde montajlı \Mounted on the conservator
A35: 24 | B35: FALSE | D35: FC4324045 | E35: Boya Son Kat RAL 9006_C5 \Touch up Paint | F35: 5 | G35: 3 | H35: ADET | N35: 6 Kg.
A36: 25 | B36: FALSE | D36: FC4324045-01 | E36: Sertleştirici \Paint Hardener | F36: 5 | G36: 3 | H36: ADET | N36: 0,7 Kg.
A37: 26 | B37: FALSE | D37: FC4324046 | E37: Kırmızı Astar Boya \Paint Red | F37: 5 | G37: 3 | H37: ADET | N37: EPOTAN HS MASTIC GRİ BA124G2305 \1.KAT ASTAR 3 KG
A38: 27 | B38: FALSE | D38: FC4324048 | E38: Gri Astar Boya \Paint Gray | F38: 5 | G38: 3 | H38: ADET | N38: YÜKSEK KATILI EPOKSİ ASTAR (RAL 7042) \ARAKAT ASTAR 3 KG
A39: 28 | B39: FALSE | D39: FC4324049 | E39: Beyaz Astar Boya \Paint White | F39: 5 | G39: 3 | H39: ADET | N39: ASTAR EPOXY SERT İLE (RAL 9010 ) \İç ASTAR 1 KG
A40: 29 | B40: FALSE | C40: BQ150 | D40: SMC | E40: Depo Konsolu \Conservator Support | F40: 24 | G40: 2 | H40: ADET | K40: T10574774 | L40: PA600-43-53-.04.00000 | M40: 11 13
A41: 30 | B41: FALSE | C41: BQ150 | D41: SMC | E41: Depo Konsol Çaprazı \Conservator Cross Support | F41: 24 | G41: 4 | H41: ADET | K41: T10574774 | L41: PA600-43-53-.04.00000 | M41: 2
...
